#VRML_SIM R2025a utf8

EXTERNPROTO "https://raw.githubusercontent.com/cyberbotics/webots/R2025a/projects/objects/backgrounds/protos/TexturedBackground.proto"
EXTERNPROTO "https://raw.githubusercontent.com/cyberbotics/webots/R2025a/projects/objects/backgrounds/protos/TexturedBackgroundLight.proto"
EXTERNPROTO "https://raw.githubusercontent.com/cyberbotics/webots/R2025a/projects/objects/floors/protos/RectangleArena.proto"
EXTERNPROTO "https://raw.githubusercontent.com/cyberbotics/webots/R2025a/projects/appearances/protos/BrushedAluminium.proto"

WorldInfo {
}
Viewpoint {
  orientation -0.19258777039245067 0.1427024452292441 0.9708480637158728 2.269539775884887
  position 858.874351450585 -999.977131448169 594.436504922207
}
TexturedBackground {
}
TexturedBackgroundLight {
}
RectangleArena {
  floorSize 700 700
}
Solid {
  translation -91.25 -218.83 -43.47
  rotation 1 0 0 4.692820414042842e-06
  children [
    HingeJoint {
    }
    Transform {
      translation 10 0 61.58
      scale 0.1 0.1 0.1
      children [
        Shape {
          appearance BrushedAluminium {
          }
          geometry Mesh {
            url [
              "../../../Desktop/wbot stl/Acople 25mm para flipper.STL"
            ]
          }
        }
      ]
    }
  ]
}
Solid {
  translation 17.69 -212.44 0
  children [
    HingeJoint {
    }
    Pose {
      children [
        Shape {
          appearance BrushedAluminium {
          }
          geometry Mesh {
            url [
              "../../../Desktop/wbot stl/Brida flipper.STL"
            ]
          }
        }
      ]
    }
  ]
  name "solid(1)"
}
Solid {
  translation 102.34 -215.76 0
  children [
    HingeJoint {
    }
    Pose {
      children [
        Shape {
          appearance BrushedAluminium {
          }
          geometry Mesh {
            url [
              "../../../Desktop/wbot stl/Rueda skie.STL"
            ]
          }
        }
      ]
    }
  ]
  name "solid(2)"
}
Solid {
  name "solid(4)"
}
Solid {
  translation 0 57.46 9.2
  children [
    HingeJoint {
    }
    Transform {
      translation 143.89 6.57243e-05 0
      rotation 0 0 1 -1.5707953071795862
      scale 0.4 0.3 0.4
      children [
        Shape {
          appearance BrushedAluminium {
          }
          geometry Mesh {
            url [
              "D:/wbot.dae/base del rescu/base de 300_2022.dae"
            ]
          }
        }
      ]
    }
  ]
  name "solid(5)"
}
Solid {
  translation -47.67 -182.84 4.49
  children [
    HingeJoint {
    }
    Transform {
      translation 0 -62.26 8.71
      scale 0.5 0.5 0.5
      children [
        Shape {
          appearance BrushedAluminium {
          }
          geometry Mesh {
            url [
              "D:/wbot.dae/base del rescu/Perfil 300mm 2x2cm.dae"
            ]
          }
        }
      ]
    }
  ]
  name "solid(6)"
}
Solid {
  translation -287.13 -253.97 -210.16
  children [
    HingeJoint {
    }
    Pose {
      children [
        Shape {
          appearance BrushedAluminium {
          }
          geometry Mesh {
            url [
              "D:/wbot.dae/base del rescu/Reductora RV40.dae"
            ]
          }
        }
      ]
    }
  ]
  name "solid(7)"
}
Solid {
  translation 351.03 125.05 70.4306
  rotation 3.3905113482557537e-09 -0.707108281185553 0.70710528118436 3.14159
  children [
    HingeJoint {
    }
    Transform {
      scale 0.3 0.3 0.3
      children [
        Shape {
          appearance BrushedAluminium {
          }
          geometry Mesh {
            url [
              "D:/wbot.dae/Oruga pequeña/orugas 3.0.dae"
            ]
          }
        }
      ]
    }
  ]
  name "solid(8)"
}
Solid {
  translation 166.82 186.27 58.6108
  rotation 1 0 0 1.5708
  children [
    HingeJoint {
    }
    Transform {
      scale 0.3 0.3 0.3
      children [
        Shape {
          appearance BrushedAluminium {
          }
          geometry Mesh {
            url [
              "D:/wbot.dae/Oruga pequeña/Tensor para oruga principal.dae"
            ]
          }
        }
      ]
    }
  ]
  name "solid(9)"
}
Solid {
  translation 148.21 81.64 8.3607
  rotation 1 0 0 1.5708
  children [
    HingeJoint {
    }
    Transform {
      scale 0.3 0.3 0.3
      children [
        Shape {
          appearance BrushedAluminium {
          }
          geometry Mesh {
            url [
              "D:/wbot.dae/Oruga pequeña/llanta dentada.dae"
            ]
          }
        }
      ]
    }
  ]
  name "solid(10)"
}
Solid {
  translation 218.16 118.1 29.3608
  rotation 1 0 0 1.5708
  children [
    HingeJoint {
    }
    Transform {
      scale 0.3 0.3 0.3
      children [
        Shape {
          appearance BrushedAluminium {
          }
          geometry Mesh {
            url [
              "D:/wbot.dae/Oruga pequeña/auxiasdasdr.dae"
            ]
          }
        }
      ]
    }
  ]
  name "solid(11)"
}
Solid {
  translation 135.84 93.14 5.4408
  rotation 1 0 0 1.5708
  children [
    HingeJoint {
    }
    Transform {
      scale 0.3 0.3 0.3
      children [
        Shape {
          appearance BrushedAluminium {
          }
          geometry Mesh {
            url [
              "D:/wbot.dae/orugas principales/Orugas principales de nieve.dae"
            ]
          }
        }
      ]
    }
  ]
  name "solid(12)"
}
Solid {
  translation 134.76 -29.99 5.44032
  rotation 1 0 0 1.5708
  children [
    HingeJoint {
    }
    Transform {
      scale 0.3 0.3 0.3
      children [
        Shape {
          appearance BrushedAluminium {
          }
          geometry Mesh {
            url [
              "D:/wbot.dae/orugas principales/Orugas principales de nieve.dae"
            ]
          }
        }
      ]
    }
  ]
  name "solid(3)"
}
Solid {
  translation 349.67 -72.82 68.541
  rotation 3.3905113482557537e-09 -0.707108281185553 0.70710528118436 3.14159
  children [
    HingeJoint {
    }
    Transform {
      scale 0.3 0.3 0.3
      children [
        Shape {
          appearance BrushedAluminium {
          }
          geometry Mesh {
            url [
              "D:/wbot.dae/Oruga pequeña/orugas 3.0.dae"
            ]
          }
        }
      ]
    }
  ]
  name "solid(13)"
}
Solid {
  translation 148.21 -43.93 8.36035
  rotation 1 0 0 1.5708
  children [
    HingeJoint {
    }
    Transform {
      scale 0.3 0.3 0.3
      children [
        Shape {
          appearance BrushedAluminium {
          }
          geometry Mesh {
            url [
              "D:/wbot.dae/Oruga pequeña/llanta dentada.dae"
            ]
          }
        }
      ]
    }
  ]
  name "solid(14)"
}
Solid {
  translation 284.89 81.64 8.3607
  rotation 1 0 0 1.5708
  children [
    HingeJoint {
    }
    Transform {
      scale 0.3 0.3 0.3
      children [
        Shape {
          appearance BrushedAluminium {
          }
          geometry Mesh {
            url [
              "D:/wbot.dae/Oruga pequeña/llanta dentada.dae"
            ]
          }
        }
      ]
    }
  ]
  name "solid(15)"
}
Solid {
  translation 264.8 -44.62 8.36015
  rotation 1 0 0 1.5708
  children [
    HingeJoint {
    }
    Transform {
      scale 0.3 0.3 0.3
      children [
        Shape {
          appearance BrushedAluminium {
          }
          geometry Mesh {
            url [
              "D:/wbot.dae/Oruga pequeña/llanta dentada.dae"
            ]
          }
        }
      ]
    }
  ]
  name "solid(16)"
}
Solid {
  translation 218.16 -104.22 29.3608
  rotation 1 0 0 1.5708
  children [
    HingeJoint {
    }
    Transform {
      scale 0.3 0.3 0.3
      children [
        Shape {
          appearance BrushedAluminium {
          }
          geometry Mesh {
            url [
              "D:/wbot.dae/Oruga pequeña/auxiasdasdr.dae"
            ]
          }
        }
      ]
    }
  ]
  name "solid(17)"
}
